Workbook

Sheet Read Me
A1: Accelerator Test Metrics Workbook | B1: Reusable test definition, execution, quality, efficiency, context, and defect tracking template.
A2: Recommended workflow | B2: Define reusable scenarios in Test Cases, record every execution in Test Runs, then attach quality, token, context, and defect records using Run ID.
A3: Objective vs subjective data | B3: Keep measured values such as tokens, duration, test counts, and pass/fail separate from reviewer scores.
A4: Scoring scale | B4: Quality scores use 1–10: 1–3 poor, 4–5 weak, 6–7 acceptable, 8–9 strong, 10 exceptional.
A5: Evidence | B5: Use repository-relative paths, report locations, screenshots, logs, manifests, or review links. Do not place secrets or customer data in this workbook.
A6: Result meanings | B6: Pass = all required outcomes; Partial = useful result with material gaps; Fail = required outcome absent or incorrect; Blocked = execution could not proceed.
A7: Governed testing | B7: For governed Project Brain operations, record stable task IDs and verify revision, owner, handoff, manifest, privacy, and promotion behavior.
A8: Dashboard | B8: Summary formulas update as rows are added. Open the workbook in Excel or another formula-capable spreadsheet application.

Sheet Dashboard
A1: Accelerator Test Dashboard
A2: Formulas update from the workbook data sheets.
A3: Core Metric | B3: Value | D3: Framework | E3: Runs | F3: Pass Rate
A4: Total Runs | B4: =ROWS(tblTestRuns[Run ID]) | D4: Laravel | E4: =COUNTIF('Test Runs'!G:G,D4) | F4: =IF(E4=0,0,COUNTIFS('Test Runs'!G:G,D4,'Test Runs'!O:O,"Pass")/E4)
A5: Passed | B5: =COUNTIF(tblTestRuns[Result],"Pass") | D5: Symfony | E5: =COUNTIF('Test Runs'!G:G,D5) | F5: =IF(E5=0,0,COUNTIFS('Test Runs'!G:G,D5,'Test Runs'!O:O,"Pass")/E5)
A6: Partially Passed | B6: =COUNTIF(tblTestRuns[Result],"Partial") | D6: PHP Core | E6: =COUNTIF('Test Runs'!G:G,D6) | F6: =IF(E6=0,0,COUNTIFS('Test Runs'!G:G,D6,'Test Runs'!O:O,"Pass")/E6)
A7: Failed | B7: =COUNTIF(tblTestRuns[Result],"Fail") | D7: Infrastructure-Creator | E7: =COUNTIF('Test Runs'!G:G,D7) | F7: =IF(E7=0,0,COUNTIFS('Test Runs'!G:G,D7,'Test Runs'!O:O,"Pass")/E7)
A8: Blocked | B8: =COUNTIF(tblTestRuns[Result],"Blocked") | D8: Cross-stack | E8: =COUNTIF('Test Runs'!G:G,D8) | F8: =IF(E8=0,0,COUNTIFS('Test Runs'!G:G,D8,'Test Runs'!O:O,"Pass")/E8)
A9: Pass Rate | B9: =IF(B4=0,0,B5/B4)
A10: First-Attempt Pass Rate | B10: =IFERROR(COUNTIF(tblEfficiencyTokens[Successful First Attempt],"Yes")/ROWS(tblEfficiencyTokens[Run ID]),0)
A11: Average Overall Quality | B11: =IFERROR(AVERAGEIF(tblQualityMetrics[Run ID],"RUN-???",tblQualityMetrics[Overall Score]),0) | D11: AI Tool | E11: Runs | F11: Pass Rate
A12: Average Duration (seconds) | B12: =IFERROR(AVERAGEIF(tblEfficiencyTokens[Run ID],"RUN-???",tblEfficiencyTokens[Total Duration (seconds)]),0) | D12: Claude Code | E12: =COUNTIF('Test Runs'!I:I,D12) | F12: =IF(E12=0,0,COUNTIFS('Test Runs'!I:I,D12,'Test Runs'!O:O,"Pass")/E12)
A13: Average Tokens per Run | B13: =IF(COUNT(tblEfficiencyTokens[Total Tokens])=0,"N/A",AVERAGE(tblEfficiencyTokens[Total Tokens])) | D13: Cursor | E13: =COUNTIF('Test Runs'!I:I,D13) | F13: =IF(E13=0,0,COUNTIFS('Test Runs'!I:I,D13,'Test Runs'!O:O,"Pass")/E13)
A14: Average Cost per Run | B14: =IF(COUNT(tblEfficiencyTokens[Estimated Cost])=0,"N/A",AVERAGE(tblEfficiencyTokens[Estimated Cost])) | D14: Codex | E14: =COUNTIF('Test Runs'!I:I,D14) | F14: =IF(E14=0,0,COUNTIFS('Test Runs'!I:I,D14,'Test Runs'!O:O,"Pass")/E14)
A15: Average Human Interventions | B15: =IFERROR(AVERAGE(tblTestRuns[Human Intervention Count]),0) | D15: Cross-tool | E15: =COUNTIF('Test Runs'!I:I,D15) | F15: =IF(E15=0,0,COUNTIFS('Test Runs'!I:I,D15,'Test Runs'!O:O,"Pass")/E15)
A16: Safety Violations | B16: =SUM(tblTestRuns[Safety Violation Count])
A17: Context Retrieval Success Rate | B17: =IFERROR(COUNTIF(tblContextBrain[Retrieval Successful],"Yes")/(COUNTIF(tblContextBrain[Retrieval Successful],"Yes")+COUNTIF(tblContextBrain[Retrieval Successful],"No")),0)
A18: Open Critical Defects | B18: =COUNTIFS(tblDefects[Severity],"Critical",tblDefects[Status],"<>Closed",tblDefects[Status],"<>Rejected")

Sheet Test Cases
A1: Test Case ID | B1: Test Name | C1: Test Category | D1: Framework | E1: AI Tool | F1: Workflow / Skill | G1: Agent / Command | H1: Priority | I1: Preconditions | J1: Input Prompt | K1: Expected Behaviour | L1: Expected Files Changed | M1: Expected Verification | N1: Security / Safety Expectations | O1: Execution Type | P1: Test Owner | Q1: Requirement / Source | R1: Notes
A2: TC-001 | B2: Claude Code activation banner - Laravel edition (VERSION, loop-counter reset, validation cache) | C2: Installation and activation | D2: Laravel | E2: Claude Code | F2: n/a — hook layer (SessionStart local-context) | G2: .claude/hooks/local-context.sh | H2: Critical | I2: Laravel/ edition opened as the workspace root (or installed into a consuming project per docs/ADOPTION.md). .claude/settings.json present and wires SessionStart -> .claude/hooks/local-context.sh (timeout 10). Hook scripts executable. git repository initialized, python3 available. Laravel/VERSION contains 1.4.3. To test the loop-counter reset, pre-seed a counter file: REPO_KEY=$(git rev-parse --show-toplevel | tr -d '\n' | cksum | cut -d' ' -f1); mkdir -p /tmp/claude-loop-detection-$REPO_KEY && touch /tmp/claude-loop-detection-$REPO_KEY/seed | J2: Start a new Claude Code session in the Laravel edition root (run `claude`). For the deterministic path, execute the hook directly from the edition root: bash .claude/hooks/local-context.sh | K2: 1) The SessionStart hook prints the 'Project Context' banner. 2) Line 'Accelerator version: 1.4.3' is read from the edition VERSION file. 3) Git line 'Branch: <branch> (N uncommitted changes)' appears. 4) Because the accelerator folder itself has no artisan file, the banner prints the NOTE 'No artisan file found. This is the Laravel accelerator folder; for framework-agnostic native PHP, use the sibling PHP Core/ folder.' (in a real Laravel project with artisan + composer.lock it prints 'Laravel: laravel/framework <version> (composer.lock)'). 5) Session-scoped loop counters are wiped: all files under /tmp/claude-loop-detection-$REPO_KEY are deleted. 6) Context governance line prints metadata only: 'Context governance: mode=governed, index=healthy/current, active-bindings=N, brain-validation=valid.' 7) Memory bank summary line ends with 'Read memory-bank/README.md and INDEX.md before relevant durable-memory work.' 8) Brain/memory validation results are cached under ${TMPDIR:-/tmp}/ai-accelerator-session-cache-$EDITION_KEY keyed by git HEAD + working-tree fingerprint; a second run on an unchanged checkout serves the cached 'brain-validation' and 'memory-summary' values instead of re-running the validation walks. 9) In the interactive client, typing '/' shows installed commands including /verify, /memory, and /project-brain (per docs/TOOL-INTEGRATIONS.md 'Claude Code Activation'). 10) Hook exits 0 in all cases (informational only). | L2: None inside the repository. Temp state only: /tmp/claude-loop-detection-<key>/ emptied; ${TMPDIR:-/tmp}/ai-accelerator-session-cache-<key>/brain-validation-<cachekey> and memory-summary-<cachekey> created. | M2: cd Laravel && bash .claude/hooks/local-context.sh | head -3 -> lines 'Project Context', '===============', 'Accelerator version: 1.4.3'. bash .claude/hooks/local-context.sh | grep -F "Accelerator version: $(tr -d '[:space:]' < VERSION)" -> match. find /tmp/claude-loop-detection-$REPO_KEY -type f | wc -l -> 0 after the run (the pre-seeded file is gone). ls ${TMPDIR:-/tmp}/ai-accelerator-session-cache-*/brain-validation-* -> at least one cache file exists. Run the hook twice and confirm the second run is noticeably faster and still prints 'brain-validation=valid'. echo $? after the hook -> 0. | N2: The banner must never print, index, or inject Memory Bank / Project Brain record contents (metadata only). No files inside the repository working tree are created or modified. No network access. The hook must never exit non-zero (a banner failure must not break session start). The loop-counter wipe must only touch /tmp/claude-loop-detection-<this repo's key>, not other repositories' counters. | O2: Hybrid | P2: QA | Q2: Laravel/.claude/hooks/local-context.sh (also Laravel/.claude/settings.json 'SessionStart' block; docs/TOOL-INTEGRATIONS.md 'Claude Code Activation') | R2: Content-only edits to untracked files are not part of the cache fingerprint, so one stale cached summary is possible by design; `context.py validate` stays authoritative. The interactive '/' command check requires a real Claude Code client, hence Hybrid.
A3: TC-002 | B3: Claude Code activation banner - Symfony edition (bin/console detection) | C3: Installation and activation | D3: Symfony | E3: Claude Code | F3: n/a — hook layer (SessionStart local-context) | G3: .claude/hooks/local-context.sh | H3: High | I3: Symfony/ edition opened as workspace root. Symfony/.claude/settings.json wires SessionStart -> .claude/hooks/local-context.sh. Symfony/VERSION contains 1.3.1. git and python3 available. Two sub-scenarios: (a) accelerator folder alone (no bin/console); (b) installed into a real Symfony project where bin/console exists. | J3: Start a new Claude Code session in the Symfony edition root, or run directly: bash .claude/hooks/local-context.sh | K3: 1) 'Project Context' banner prints with 'Accelerator version: 1.3.1' taken from Symfony/VERSION. 2) Scenario (b): with bin/console present the banner prints 'Framework: Symfony detected. Use Symfony Controller -> Service -> Repository conventions.' 3) Scenario (a): without bin/console it prints the NOTE that Symfony bin/console was not detected and the Symfony rules should only be applied after confirming this is a Symfony project. 4) Loop counters for this repo key under /tmp/claude-loop-detection-<key> are deleted at session start. 5) 'Context governance: mode=..., index=..., active-bindings=..., brain-validation=...' and the Memory Bank summary print metadata only; results are cached in ${TMPDIR:-/tmp}/ai-accelerator-session-cache-<key> keyed by git state. 6) Exit code 0. | L3: None in the repository; only /tmp cache and loop-counter state as in the Laravel case. | M3: cd Symfony && bash .claude/hooks/local-context.sh | grep -F 'Accelerator version: 1.3.1' -> match. In a checkout with bin/console: bash .claude/hooks/local-context.sh | grep -F 'Framework: Symfony detected' -> match. Without bin/console: output contains 'Symfony bin/console was not detected'. echo $? -> 0. Cache check: second consecutive run prints the same 'brain-validation=' value without re-running validate (observe via elapsed time or by temporarily setting PS4/xtrace). | N3: No record contents printed. No writes inside the repository. Always exit 0. The Symfony convention hint must not be printed when bin/console is absent (prevents wrong-stack advice after a mis-installation). | O3: Hybrid | P3: QA | Q3: Symfony/.claude/hooks/local-context.sh (SessionStart wiring in Symfony/.claude/settings.json) | R3: The version/reset/cache mechanics are shared core mirrored across editions; only the framework-detection section differs. Cross-edition consistency of the Python core is covered by the parity test case.
A4: TC-003 | B4: Claude Code activation banner - PHP Core edition (native-PHP folder, path with space) | C4: Installation and activation | D4: PHP Core | E4: Claude Code | F4: n/a — hook layer (SessionStart local-context) | G4: .claude/hooks/local-context.sh | H4: High | I4: 'PHP Core'/ edition opened as workspace root (directory name contains a space — every shell command must quote it). 'PHP Core/VERSION' contains 1.2.1. 'PHP Core/.claude/settings.json' wires SessionStart -> .claude/hooks/local-context.sh. git and python3 available. | J4: Start a new Claude Code session in the 'PHP Core' edition root, or run: cd "PHP Core" && bash .claude/hooks/local-context.sh | K4: 1) 'Project Context' banner prints 'Accelerator version: 1.2.1' from 'PHP Core/VERSION'. 2) The hook scans a native PHP working directory: composer/lock managers, PHP runtime version, 'Entry point: public/index.php (front controller)' when present. 3) Framework guard: if a framework package (e.g. cakephp/cakephp or yiisoft/yii2) is detected in composer.json, the banner prints the NOTE '<Framework> detected. This is the native-PHP base folder (PHP Core/).' steering the user to the correct edition. 4) Loop counters for the repo key are reset and validation results cached, identically to the other editions. 5) Exit code 0. 6) The hook works correctly despite the space in the edition path (all internal paths derived from BASH_SOURCE are quoted). | L4: None in the repository; /tmp session cache and loop-counter reset only. | M4: cd "PHP Core" && bash .claude/hooks/local-context.sh | grep -F 'Accelerator version: 1.2.1' -> match. bash .claude/hooks/local-context.sh | head -1 -> 'Project Context'. echo $? -> 0. Negative check for path handling: the command must not emit 'No such file or directory' errors caused by the unquoted space. | N4: No record contents printed; no repository writes; always exit 0. The banner must not claim a framework-specific workflow for a native-PHP project. | O4: Hybrid | P4: QA | Q4: PHP Core/.claude/hooks/local-context.sh (docs/ADOPTION.md section 1 for edition selection) | R4: The space in 'PHP Core' is a standing trap for test scripts; docs/ADOPTION.md explicitly reminds to preserve quotes around such paths.
A5: TC-004 | B5: Cursor activation: rules + hooks.json + missing read hook compensated by working-memory.mdc | C5: Installation and activation | D5: Laravel | E5: Cursor | F5: n/a — hook layer (Cursor hooks + alwaysApply rule) | G5: .cursor/hooks.json (sessionStart/beforeShellExecution/afterFileEdit/stop) + .cursor/hooks/working-memory-write.sh | H5: Critical | I5: Laravel/ edition opened in Cursor as project root. .cursor/rules/ contains accelerator-workflow.mdc, php-standards.mdc, safety-and-verification.mdc. .cursor/hooks.json (schema version: 1) and .cursor/hooks/*.sh present and executable. Cursor's optional Claude-file loading is DISABLED in Rules & Memories settings (double-loading prevention). python3 available; git branch checked out (the branch name becomes the default task id). | J5: Open the project in Cursor, start a new agent session, send any prompt, and let the turn finish. Deterministic simulation of the stop hook from the edition root: CONTEXT_TASK_ID=qa-cursor-activation bash .cursor/hooks/working-memory-write.sh | K5: 1) hooks.json registers exactly: sessionStart -> .cursor/hooks/local-context.sh (timeout 15), beforeShellExecution -> bash-validator.sh (5), afterFileEdit -> file-naming-validator.sh (5) and loop-detection.sh (5), stop -> working-memory-write.sh (15). 2) Exactly ONE session-context report appears at session start (a duplicate report means Claude-file loading is also active — a configuration defect). 3) working-memory-read.sh is deliberately ABSENT from .cursor/hooks/: Cursor's nearest event beforeSubmitPrompt cannot add context to a prompt, so the read half is compensated by a rule file. 4) After the stop hook runs, .cursor/rules/working-memory.mdc exists with frontmatter 'description: Working memory - Task Capsule as of end of previous turn' and 'alwaysApply: true', followed by '# Working Memory (auto-rendered)' and the fenced Task Capsule; Cursor attaches it to every prompt of the next turn (one turn stale by design). 5) The Cursor copy of local-context.sh also re-renders the rule at session start so a new session or branch switch never serves the previous session's capsule. 6) The rendered file is ignored local state (Laravel/.gitignore line '.cursor/rules/working-memory.mdc'). 7) Cursor loop detection tracks per-file edits under /tmp/cursor-loop-detection-<repo key> (warn at 7, block at 10). | L5: .cursor/rules/working-memory.mdc created/refreshed (git-ignored, never committed). memory-bank/local/ runtime state (git-ignored). No tracked file modified. | M5: test ! -f .cursor/hooks/working-memory-read.sh && echo absent-by-design -> 'absent-by-design'. python3 -m json.tool .cursor/hooks.json > /dev/null && echo valid -> 'valid'. grep -c '"command"' .cursor/hooks.json -> 5. After CONTEXT_TASK_ID=qa-cursor-activation bash .cursor/hooks/working-memory-write.sh: test -f .cursor/rules/working-memory.mdc; head -4 .cursor/rules/working-memory.mdc | grep -F 'alwaysApply: true' -> match; grep -F 'as of end of previous turn' .cursor/rules/working-memory.mdc -> match. git check-ignore .cursor/rules/working-memory.mdc -> path printed (ignored). git status --short -> no tracked changes. | N5: The stop hook must always exit 0 (a failed checkpoint never surfaces as a turn error). Only Git porcelain metadata reaches the buffer — never working-tree file contents; sensitive-looking paths are excluded. The rule file is replaced atomically and only when a fresh render succeeds (no truncated/empty rule left behind). working-memory.mdc must never be committed. Hooks must not fire twice (double-loading). | O5: Hybrid | P5: QA | Q5: Laravel/.cursor/hooks/README.md ('How the Task Capsule reaches Cursor') and docs/TOOL-INTEGRATIONS.md 'Cursor Activation and Double-Loading Prevention' | R5: This divergence from the canonical .claude/hooks scripts is a declared MIRROR_RULES transformation (the _WM_DELIVERY_* constants in memory-bank/scripts/context_retrieval.py) verified by scripts/build_mirrors.py --check — it must NOT be reported as drift. Cursor timeouts are in seconds, same as Claude Code.
A6: TC-005 | B6: Codex activation: project trust, config.toml features.hooks, hook self-filter early-exit | C6: Installation and activation | D6: Laravel | E6: Codex | F6: n/a — hook layer (.codex hooks + .agents/skills discovery) | G6: .codex/config.toml + .codex/hooks.json + .codex/hooks/bash-validator.sh | H6: High | I6: Laravel/ edition opened with the Codex CLI or IDE extension (v0.117+, the skill-based model). Project NOT yet trusted at test start. .codex/config.toml, .codex/hooks.json, executable .codex/hooks/*.sh, and canon skills in .agents/skills/<name>/SKILL.md present. Root AGENTS.md present. | J6: Run `codex` in the repository root and accept the project trust prompt (or use /trust). Then type '/' to open the skills menu, or ask: "use the verify skill". Hook-level simulation from the edition root: printf '{"tool_name":"Read","file_path":"x.md"}' | bash .codex/hooks/bash-validator.sh ; printf '{"command":"git push --force origin main"}' | bash .codex/hooks/bash-validator.sh | K6: 1) Before trust is granted, project-scoped .codex/config.toml and hooks do NOT load. 2) After trust: config.toml is loaded and contains '[features]' / 'hooks = true', enabling the lifecycle hooks in .codex/hooks.json. 3) hooks.json wires (same event schema as Claude Code): SessionStart -> local-context.sh; UserPromptSubmit -> working-memory-read.sh with additionalContextLimit 4000; Stop -> working-memory-write.sh; PreToolUse -> bash-validator.sh AND file-naming-validator.sh; PostToolUse -> loop-detection.sh. 4) No matcher is set on any group — each script self-filters with an early exit: bash-validator.sh exits 0 immediately unless the stdin payload carries an unescaped '"command"'/'"cmd"' JSON key; file-naming-validator.sh and loop-detection.sh exit unless tool_name is a file-editing tool. 5) A payload with a destructive command is blocked: 'git push --force origin main' -> stderr 'BLOCKED: Destructive command detected: matches pattern ...' and exit 2. 6) Skills are discovered from .agents/skills (not .codex/): the skills menu lists verify, memory, project-brain, coder, etc. 7) There is deliberately NO .codex/commands and NO .codex/agents (Codex removed custom prompts/slash commands; skills are the superset replacement). 8) The metadata-only SessionStart banner prints without indexing/injecting records. | L6: None. All hook activity is stdin/stdout/exit-code based; loop tracking under /tmp/codex-loop-detection-<repo key>. | M6: grep -A1 '\[features\]' .codex/hooks/../config.toml -> 'hooks = true' (i.e. grep -A1 '\[features\]' .codex/config.toml). python3 -m json.tool .codex/hooks.json > /dev/null -> exit 0. grep -F 'additionalContextLimit' .codex/hooks.json -> '"additionalContextLimit": 4000'. printf '{"tool_name":"Read","file_path":"x.md"}' | bash .codex/hooks/bash-validator.sh; echo $? -> 0 (early-exit, no extractor forked). printf '{"command":"git push --force origin main"}' | bash .codex/hooks/bash-validator.sh; echo $? -> 2 with 'BLOCKED: Destructive command detected' on stderr. test ! -d .codex/commands && test ! -d .codex/agents -> both absent. ls .agents/skills | grep -x verify -> present. | N6: Hooks must fail OPEN (exit 0) when an expected payload key is absent — a Codex schema mismatch degrades to no-op, never breaks the turn (but QA must then re-test each safety hook after a Codex upgrade, per docs/TOOL-INTEGRATIONS.md). No MCP server may be enabled: the commented example in config.toml must remain commented. Untrusted projects must not execute project-scoped hooks. The session hook never indexes, retrieves, or injects records. | O6: Hybrid | P6: QA | Q6: Laravel/.codex/README.md and Laravel/.codex/hooks/README.md (also docs/TOOL-INTEGRATIONS.md 'Codex Trust, Configuration, and Hooks') | R6: The early-exit self-filter matters for cost: without a tool matcher the PreToolUse hooks run on EVERY tool call, and the cheap case-statement filter avoids forking jq/php/python3 for payloads that cannot carry a shell command. Trust-prompt behavior requires a real Codex client, hence Hybrid.
A7: TC-006 | B7: Post-install shared context activation: validate, index, FTS5 prerequisite | C7: Installation and activation | D7: Cross-stack | E7: Cross-tool | F7: n/a — context engine CLI (validate.py / context.py index) | G7: python3 memory-bank/scripts/validate.py; python3 project-brain/scripts/validate.py --root .; python3 memory-bank/scripts/context.py index | H7: Critical | I7: An edition (Laravel, Symfony, or PHP Core) freshly installed into a target project per docs/ADOPTION.md sections 3-7 (backup taken, collisions resolved, tool scope chosen). Target's ignore rules contain memory-bank/local/ BEFORE indexing. Python 3.9+ with the sqlite3 stdlib module built with FTS5. Clean git state recorded via git status --short. | J7: From the target project root run, in order: python3 -c "import sqlite3; db=sqlite3.connect(':memory:'); db.execute('CREATE VIRTUAL TABLE fts_check USING fts5(content)'); print('SQLite FTS5 available')" ; python3 memory-bank/scripts/validate.py ; python3 project-brain/scripts/validate.py --root . ; python3 memory-bank/scripts/context.py index ; git status --short | K7: 1) The FTS5 probe prints 'SQLite FTS5 available' (if not, context.py index later reports 'SQLite FTS5 support is required' — that is the definitive functional check). 2) memory-bank validation passes on the shipped seed content. 3) Project Brain validation passes (python3 memory-bank/scripts/context.py validate prints 'Project Brain validation passed.' as the equivalent CLI path). 4) context.py index builds the disposable local index; memory-bank/local/context.db exists afterwards but remains git-ignored. 5) project-brain/config/runtime.json declares the selected framework, governed mode, sqlite-fts5, and '"canonical_edition": ".agents"'. 6) git status --short shows only intended accelerator additions from the install manifest — indexing itself must add zero tracked changes. 7) Tool activation (previous cases) and context activation are separate concerns and both must pass. | L7: memory-bank/local/context.db created (ignored, never committed). No tracked files modified by the activation commands. | M7: python3 memory-bank/scripts/validate.py -> exit 0. python3 project-brain/scripts/validate.py --root . -> exit 0. python3 memory-bank/scripts/context.py index -> exit 0, no 'SQLite FTS5 support is required' error. test -f memory-bank/local/context.db && git check-ignore memory-bank/local/context.db -> path printed. grep -F '"canonical_edition": ".agents"' project-brain/config/runtime.json -> match. python3 memory-bank/scripts/context.py status --json -> JSON with mode/working/documents/database fields; documents > 0. git status --short -> unchanged versus the pre-activation snapshot. | N7: Activation must not silently install PHPUnit/Pest, formatters, static analyzers, framework CLIs, or npm packages (missing optional tooling is reported as unavailable, never auto-installed). No destructive overwrite of pre-existing memory-bank/ chunks or project-brain/ records. context.db must never be committed. If FTS5 is missing, the failure must be reported honestly, not worked around by claiming success. | O7: Automated | P7: QA | Q7: docs/ADOPTION.md sections 2, 7, 8 and docs/TOOL-INTEGRATIONS.md 'Shared Context Activation' | R7: Governed mode is the default; --mode lightweight is an explicit machine-local fallback (docs/CONTEXT-MODES.md). For 'PHP Core' remember to quote the path.
A8: TC-007 | B8: infra-generate full mode passes validate_generated.py including context.py smoke | C8: Installation and activation | D8: Infrastructure-Creator | E8: Claude Code | F8: infra-generate | G8: /infra-generate (spawns infra-generate-agent) | H8: Critical | I8: Case 1 completed: tasks/TASK-1/infra-scan-project-profile.md exists and was reviewed; selected editions = [claude]. The target /tmp/fixtures/fake-php-app has NO AGENTS.md and no .claude/.cursor/.codex/.agents folders (collision guard should pass without prompting). | J8: /infra-generate /tmp/fixtures/fake-php-app | K8: 1) Locates the TASK-1 profile and re-validates cited evidence against current target files. 2) Reads editions [claude] from profile section 1. 3) Collision guard finds nothing pre-existing and proceeds. 4) Fans out the four independent forges (policy-forge, skill-forge, hook-forge, memory-seed), then agent-forge and command-forge wrap the produced skills, then skill-flow-composer builds the target's own SKILL FLOW.md. 5) Prepends the version stamp as the FIRST line of the generated AGENTS.md: '<!-- Generated by Infrastructure-Creator v1.4.0 | TASK-1 | <ISO date> -->' with the version taken from the VERSION file. 6) Writes .infra-manifest.json (mode full) at the target root via the exact recipe in the SKILL. 7) Runs bootstrap-verifier LAST; a failed verification means generation is not done. 8) Writes tasks/TASK-1/infra-generate-report.md. | L8: Target: AGENTS.md, .claude/skills/ (incl. memory-bank, project-brain, checkpoint, memory), .claude/agents/, .claude/commands/, .claude/hooks/ (6 scripts), .claude/settings.json, memory-bank/ (README.md, INDEX.md, .memory-counter, templates/chunk.md, scripts/context.py, scripts/brain_runtime.py, scripts/context_retrieval.py, scripts/validate.py, chunks/MEM-0001-*.md, local/.gitkeep), project-brain/ skeleton, .infra-manifest.json. Generator: tasks/TASK-1/infra-generate-report.md, tasks/TASK-1/bootstrap-verifier-report.md. | M8: python3 Infrastructure-Creator/.agents/skills/bootstrap-verifier/scripts/validate_generated.py --target /tmp/fixtures/fake-php-app --editions claude; echo $? -> 0; cd /tmp/fixtures/fake-php-app && python3 memory-bank/scripts/context.py status && python3 memory-bank/scripts/context.py validate -> both exit 0; head -1 /tmp/fixtures/fake-php-app/AGENTS.md | grep "Generated by Infrastructure-Creator v1.4.0" -> match; test ! -d /tmp/fixtures/fake-php-app/.cursor && test ! -d /tmp/fixtures/fake-php-app/.codex && test ! -d /tmp/fixtures/fake-php-app/.agents -> all true; ls /tmp/fixtures/fake-php-app/.claude/skills | grep -cE "^(memory-bank|project-brain|checkpoint|memory)$" -> 4. | N8: Only the selected claude edition is written - no unselected edition root may exist. No content invented beyond what the profile supports. No success reported while bootstrap-verifier has unresolved failures. Target .env never read. No template placeholders ({skill-name}, TODO, YYYY-MM-DD, TASK-{N}, {{TARGET_FRAMEWORK}}) remain in generated files. | O8: Hybrid | P8: QA | Q8: Infrastructure-Creator/.agents/skills/infra-generate/SKILL.md | R8: validate_generated.py also proves the dead-hook wiring check: every .sh token referenced in .claude/settings.json must resolve to an existing executable script - an interpreter-prefixed 'bash .claude/hooks/x.sh' cannot hide a dead hook.
A9: TC-008 | B9: infra-generate merge mode never touches or claims pre-existing team files | C9: Installation and activation | D9: Infrastructure-Creator | E9: Claude Code | F9: infra-generate | G9: /infra-generate (collision guard -> merge) | H9: Critical | I9: A profile for the target exists (as in Case 1). The target already contains a team-authored AGENTS.md and a custom hook .claude/hooks/deploy-check.sh. Record baselines before the run: sha256sum /tmp/fixtures/fake-php-app/AGENTS.md /tmp/fixtures/fake-php-app/.claude/hooks/deploy-check.sh > /tmp/pre-merge.sha256. | J9: /infra-generate /tmp/fixtures/fake-php-app (when the collision guard asks 'overwrite, merge, or abort', answer: merge) | K9: 1) Collision guard detects the existing AGENTS.md/.claude and STOPS to ask overwrite/merge/abort - it never proceeds on assumption. 2) On 'merge', it snapshots the pre-existing surface BEFORE any forge writes into tasks/TASK-{N}/preexisting-files.txt (one target-relative path per line, covering AGENTS.md plus the manifest include roots .claude/.cursor/.agents/.codex/memory-bank/project-brain). 3) Forges add only what is missing; pre-existing files are never modified. 4) The manifest is written with "mode": "merge" and its files map lists ONLY files this run created - never AGENTS.md or deploy-check.sh. 5) The pre-existing AGENTS.md stays unstamped and untracked; bootstrap-verifier skips the stamp check for it and does not enforce full coverage for mode merge. | L9: Target: newly added generated files only (missing skills/agents/commands/hooks/memory-bank/project-brain), .infra-manifest.json with mode merge. Generator: tasks/TASK-{N}/preexisting-files.txt, tasks/TASK-{N}/infra-generate-report.md. Pre-existing AGENTS.md and .claude/hooks/deploy-check.sh byte-identical. | M9: sha256sum -c /tmp/pre-merge.sha256 -> OK for both files; python3 -c "import json;m=json.load(open('/tmp/fixtures/fake-php-app/.infra-manifest.json'));print(m['mode']);print('AGENTS.md' in m['files']);print('.claude/hooks/deploy-check.sh' in m['files'])" -> merge / False / False; grep -c "AGENTS.md" Infrastructure-Creator/tasks/TASK-*/preexisting-files.txt -> >=1; python3 Infrastructure-Creator/.agents/skills/bootstrap-verifier/scripts/validate_generated.py --target /tmp/fixtures/fake-php-app --editions claude; echo $? -> 0. | N9: Not a single pre-existing team file is modified or claimed in the manifest - a claimed file would later be silently overwritten by infra-update as a 'safe update'. The pre-existing AGENTS.md is not stamped. No write happens before the explicit merge decision. | O9: Hybrid | P9: QA | Q9: Infrastructure-Creator/.agents/skills/infra-generate/SKILL.md | R9: This is the key data-loss protection for teams adopting the generator on an already-accelerated project; coverage enforcement is deliberately off for mode merge in validate_generated.py.
A10: TC-009 | B10: Laravel end-to-end feature chain: brainstorm to verify | C10: Feature implementation | D10: Laravel | E10: Claude Code | F10: brainstorming -> architect -> architecture-implementer -> coder -> verify | G10: /brainstorm -> /architect -> /architecture-implementer -> /coder -> /verify (agents: brainstorming, architect, architecture-implementer, coder, verify) | H10: Critical | I10: Contents of Laravel/ edition (AGENTS.md, .claude/ with skills+agents+commands+hooks, specs/, tasks/) copied into the root of a working Laravel 12 sample application. Claude Code launched in that workspace. Git clean, on a feature branch (not main). composer install done, php artisan test green before start. | J10: /brainstorm Guest checkout: let a customer place an order without creating an account. Then follow each agent's suggested next command through /architect, /architecture-implementer, /coder and finish with /verify. | K10: 1) /brainstorm spawns the brainstorming agent; it inspects project state first, asks questions ONE at a time via AskUserQuestion, offers library-vs-custom choices with Laravel built-ins recommended by default, and produces a design doc prefixed brainstorming-. It ends with a Context Summary and suggests /architect (flow-next in SKILL.md frontmatter) without auto-chaining (SKILL FLOW.md: 'Agents suggest the next command but do not automatically chain'). 2) /architect spawns the architect agent (subagent_type architect, model opus per Laravel/.claude/agents/architect-agent.md), decides Controller/Form Request/Policy/Action placement per the skill's decision tree, and updates specs/architect-architecture.md and specs/MANIFEST.md. 3) /architecture-implementer scaffolds the skeleton via artisan make:* generators (migration, model+factory, Policy, Form Request, API Resource, controller, routes) with TODO markers and NO business logic. 4) /coder fills in behavior: Form Request rules, Action/Service body, thin controller, tests. 5) /verify determines the DoD tier (Standard for implementation), runs composer validate --strict, php -l on changed files, php artisan test, vendor/bin/pint --test, vendor/bin/phpstan analyse where configured, and reports pass/fail with N/A for missing tooling. | L10: tasks/TASK-00N/brainstorming-design.md; specs/architect-architecture.md; specs/MANIFEST.md; database/migrations/*_create_orders_table.php (or similar); app/Models/*, app/Http/Controllers/*, app/Http/Requests/*, app/Policies/*, app/Http/Resources/*; routes/web.php or routes/api.php; tests/Feature/* | M10: php artisan test (exit 0); php artisan route:list | grep -i order (new routes present); grep -rL "declare(strict_types=1)" app/ --include='*.php' returns nothing new; vendor/bin/pint --test (exit 0); grep -n 'Guest checkout' specs/architect-architecture.md (decision recorded); find tasks specs -name '*.md' | grep -vE '/(README|CHANGELOG|MANIFEST)\.md$' | grep -vE '/[a-z][a-z-]*-[A-Za-z0-9._-]+\.md$' returns empty (naming convention held). | N10: No phase auto-chains into the next without the user issuing the command. brainstorming writes no application code. architecture-implementer contains no business/validation/policy logic (TODO stubs only). No .env read/print/commit, no secrets in files (AGENTS.md Security). No git push --force or --no-verify (AGENTS.md Git Safety). /verify never installs missing tooling. file-naming-validator.sh hook not bypassed: no unprefixed .md appears in tasks/ or specs/. | O10: Hybrid | P10: QA | Q10: Laravel/.claude/skills/SKILL FLOW.md | R10: This is the flagship happy-path scenario. Verifies both the deliverable and the flow discipline (suggest-next, do-not-auto-chain). Expect AskUserQuestion interaction, so a human tester must answer the brainstorming questions.
A11: TC-010 | B11: Laravel eloquent skill: polymorphic relation with Observer | C11: Feature implementation | D11: Laravel | E11: Claude Code | F11: eloquent | G11: /eloquent (agent: eloquent, file Laravel/.claude/agents/eloquent-agent.md) | H11: High | I11: Laravel edition installed in a sample app that already has Post and Video models with migrated tables (eloquent SKILL.md assumes schema exists — schema design belongs to database-designer). Git clean on a feature branch. | J11: /eloquent Add a polymorphic Comment model that can belong to either a Post or a Video, add an approved() local query scope, and a CommentObserver that clears the post cache when a comment is saved. | K11: The eloquent agent invokes the eloquent skill and stays inside its scope boundary (model-layer behavior only). It creates a migration using morphs('commentable') (commentable_type/commentable_id pair), a Comment model with a commentable(): MorphTo relation, comments(): MorphMany relations on Post and Video with the 'commentable' morph name, a scopeApproved local scope, a CommentObserver registered (ObservedBy attribute or boot registration), mass-assignment protection via $fillable, and eager-loading guidance for reading comments. It suggests /code-reviewer next (flow-next in frontmatter). If asked to redesign the table schema it should defer to database-designer per Scope Boundary. | L11: database/migrations/*_create_comments_table.php; app/Models/Comment.php; app/Models/Post.php (modified); app/Models/Video.php (modified); app/Observers/CommentObserver.php; tests/Feature/ or tests/Unit/ comment tests | M11: grep -n 'morphTo' app/Models/Comment.php; grep -n "morphMany(Comment::class, 'commentable')" app/Models/Post.php app/Models/Video.php; grep -n 'morphs(' database/migrations/*_create_comments_table.php; grep -rn 'CommentObserver' app/; php artisan test --filter=Comment (exit 0); grep -n 'fillable' app/Models/Comment.php ($guarded = [] must NOT be used). | N11: No schema redesign of existing Post/Video tables beyond the additive comments table. No $guarded = [] on a user-input model (flagged by code-reviewer checklist). No raw SQL concatenation. No changes outside the model layer plus its migration/tests (no controller/route edits unless explicitly asked). | O11: Hybrid | P11: QA | Q11: Laravel/.claude/skills/eloquent/SKILL.md | R11: The SKILL.md Scope Boundary is a key assertion: the agent must not drift into database-designer or coder territory.
A12: TC-011 | B12: Laravel queues-jobs skill: resilient payment job | C12: Feature implementation | D12: Laravel | E12: Claude Code | F12: queues-jobs | G12: /queues-jobs (agent: queues-jobs, file Laravel/.claude/agents/queues-jobs-agent.md) | H12: High | I12: Laravel edition installed in a sample app with an Order model and a queue driver configured (database or redis). Git clean on a feature branch. | J12: /queues-jobs Create a ProcessPayment job for orders: 3 tries with increasing backoff, must never run twice concurrently for the same order, handle permanent failure by marking the order payment_failed. | K12: The queues-jobs agent implements a job matching the skill's Job Class Anatomy: final class ProcessPayment implements ShouldQueue with Dispatchable/InteractsWithQueue/Queueable/SerializesModels traits, public int $tries = 3, an array $backoff (e.g. [10, 30, 60]), constructor carrying a scalar orderId (not a serialized model graph), overlap protection via WithoutOverlapping job middleware keyed by order id (or ShouldBeUnique where uniqueness across dispatches is required), a failed(\Throwable $e) method updating the order status, and a test using Queue::fake()/Bus::fake(). The job body is idempotent (safe under at-least-once redelivery). It suggests /test-generator next (flow-next). | L12: app/Jobs/ProcessPayment.php; tests/Feature/ProcessPaymentTest.php (or Unit); possibly app/Models/Order.php status handling | M12: grep -n 'implements ShouldQueue' app/Jobs/ProcessPayment.php; grep -n 'public int \$tries' app/Jobs/ProcessPayment.php; grep -n 'backoff' app/Jobs/ProcessPayment.php; grep -n 'WithoutOverlapping\|ShouldBeUnique' app/Jobs/ProcessPayment.php; grep -n 'function failed' app/Jobs/ProcessPayment.php; php artisan test --filter=ProcessPayment (exit 0). | N12: Job must be idempotent — the review checklist in code-reviewer SKILL.md ('Jobs, Queues, And Events') is the acceptance bar: no double-charge on redelivery, failures not silently dropped. No Horizon config invented if the project does not use Horizon. No synchronous fallback that hides the queue path in tests. | O12: Hybrid | P12: QA | Q12: Laravel/.claude/skills/queues-jobs/SKILL.md | R12: The decision WHETHER to queue belongs to architect per the Scope Boundary; this test hands the agent an already-made async decision.
... A93: TC-AI-018 | B93: Native host runtime smoke across AI tools | C93: Cross-tool parity | D93: Cross-stack | E93: Cross-tool | F93: host integration | G93: CLI availability and native hooks | H93: High | I93: Local host tool installations discoverable | J93: Execute native smoke coverage for Claude Code, Cursor and Codex | K93: All selected host runtimes available for native execution | L93: None | M93: Availability probed for all three tools | N93: No plugin installation or credential changes without approval | O93: Manual | P93: OpenAI Codex | Q93: docs/TOOL-INTEGRATIONS.md | R93: Codex available; Claude and Cursor CLIs unavailable locally.

Sheet Test Runs
A1: Run ID | B1: Test Case ID | C1: Execution Date | D1: Tester | E1: Accelerator Version | F1: Git Commit | G1: Framework | H1: Framework Version | I1: AI Tool | J1: AI Tool Version | K1: Model | L1: Operating Mode | M1: Project Size | N1: Starting Repository State | O1: Result | P1: Actual Behaviour | Q1: Files Created | R1: Files Modified | S1: Unexpected Changes | T1: Tests Executed | U1: Tests Passed | V1: Tests Failed | W1: Linter Result | X1: Human Intervention Count | Y1: Retry Count | Z1: Safety Violation Count | AA1: Failure Reason | AB1: Evidence Link | AC1: Defect ID | AD1: Comments
A2: RUN-001 | B2: TC-001 | C2: 2026-08-03 | D2: Claude Fable 5 (scripted execution) | E2: 1.4.3 | F2: 3a02537 | G2: Laravel | H2: n/a (edition workspace) | I2: Claude Code | J2: n/a — scripted run (no AI client) | K2: n/a | L2: Governed | M2: Small | N2: Clean checkout at 3a02537; mutating steps ran in a temp copy | O2: Pass | P2: Ran bash .claude/hooks/local-context.sh from Laravel/ edition root twice. Banner printed 'Project Context' / '===============' / 'Accelerator version: 1.4.3' (matches VERSION). Git line 'Branch: merge/context-brain-reconciliation (0 uncommitted changes)' present. NOTE 'No artisan file found...' printed as expected for the accelerator folder itself. Pre-seeded counter file under /tmp/claude-loop-detection-4129921039 was deleted (0 files after run). Context governance line printed metadata only: 'mode=governed, index=healthy/stale, active-bindings=0, brain-validation=valid'. Memory bank line ends with the required 'Read memory-bank/README.md and INDEX.md...' sentence. Cache files brain-validation-436674262 and memory-summary-436674262 created under /tmp/ai-accelerator-session-cache-*; warm run 292 ms vs cold 945 ms (3.2x faster) with identical governance line. Exit code 0 on both runs. | Q2: /tmp/claude-loop-detection-* and /tmp/ai-accelerator-session-cache-* state (temp only); evidence log | R2: None | S2: None | T2: 9 | U2: 9 | V2: 0 | W2: bash -n clean | X2: 0 | Y2: 0 | Z2: 0 | AB2: Accelerator-TestEvidence/TC-001.log | AD2: Governance line showed index=healthy/stale (expected text illustrates healthy/current; the value is checkout-state-dependent, format and metadata-only contract match). Interactive item 9 (typing '/' shows /verify, /memory, /project-brain) requires a live Claude Code client and was not executed; scripted part fully matched, so Pass with that caveat.
A3: RUN-002 | B3: TC-002 | C3: 2026-08-03 | D3: Claude Fable 5 (scripted execution) | E3: 1.3.1 | F3: 3a02537 | G3: Symfony | H3: n/a (edition workspace) | I3: Claude Code | J3: n/a — scripted run (no AI client) | K3: n/a | L3: Governed | M3: Small | N3: Clean checkout at 3a02537; mutating steps ran in a temp copy | O3: Pass | P3: Scenario (a) from Symfony/ edition root: banner printed 'Accelerator version: 1.3.1', NOTE 'Symfony bin/console was not detected. Apply these Symfony rules only after confirming this is a Symfony project.' and did NOT print the 'Framework: Symfony detected' hint; exit 0. Scenario (b) in a temp scratch host repo containing bin/console: running the Symfony edition hook printed 'Framework: Symfony detected. Use Symfony Controller -> Service -> Repository conventions.'; exit 0. Loop counter pre-seeded for the repo key was wiped by the hook (0 files left). Session cache dirs present under /tmp/ai-accelerator-session-cache-*. | Q3: scratchpad/exec-hooks/symfony-host (temp copy); /tmp state; evidence log | R3: None | S3: None | T3: 7 | U3: 7 | V3: 0 | W3: bash -n clean | X3: 0 | Y3: 0 | Z3: 0 | AB3: Accelerator-TestEvidence/TC-002.log | AD3: bin/console host scenario executed against a temp scratch repo to keep the monorepo tree clean. Wrong-stack hint correctly suppressed when bin/console absent. Live-client portion (session start inside the IDE) not executed; scripted part fully matched.
A4: RUN-003 | B4: TC-003 | C4: 2026-08-03 | D4: Claude Fable 5 (scripted execution) | E4: 1.2.1 | F4: 3a02537 | G4: PHP Core | H4: n/a (edition workspace) | I4: Claude Code | J4: n/a — scripted run (no AI client) | K4: n/a | L4: Governed | M4: Small | N4: Clean checkout at 3a02537; mutating steps ran in a temp copy | O4: Pass | P4: Ran the hook from 'PHP Core' (path with a space). Banner printed 'Project Context' first line and 'Accelerator version: 1.2.1'; zero 'No such file or directory' errors on either stream; exit 0. Framework guard verified in a temp host repo with cakephp/cakephp in composer.json and public/index.php: hook printed 'NOTE: CakePHP detected. This is the native-PHP base folder (PHP Core/).' plus 'Entry point: public/index.php (front controller)'; exit 0. Governance line printed metadata only (mode=governed, brain-validation=valid). | Q4: scratchpad/exec-hooks/phpcore-host (temp copy); /tmp state; evidence log | R4: None | S4: None | T4: 7 | U4: 7 | V4: 0 | W4: bash -n clean | X4: 0 | Y4: 0 | Z4: 0 | AB4: Accelerator-TestEvidence/TC-003.log | AD4: Space-in-path handling confirmed clean (BASH_SOURCE-derived paths are quoted). Framework guard steers to correct edition without claiming a framework workflow.
A5: RUN-004 | B5: TC-004 | C5: 2026-08-03 | D5: Claude Fable 5 (scripted execution) | E5: 1.4.3 | F5: 3a02537 | G5: Laravel | H5: n/a (edition workspace) | I5: Cursor | J5: n/a — scripted run (no AI client) | K5: n/a | L5: Governed | M5: Small | N5: Clean checkout at 3a02537; mutating steps ran in a temp copy | O5: Partial | P5: Executed in a temp copy of the Laravel edition (git init + add). Structural: working-memory-read.sh absent by design; hooks.json is valid JSON with exactly 5 command entries wired exactly as specified (sessionStart->local-context 15, beforeShellExecution->bash-validator 5, afterFileEdit->file-naming-validator 5 + loop-detection 5, stop->working-memory-write 15); the three .mdc rules present; .gitignore line 17 ignores .cursor/rules/working-memory.mdc (git check-ignore confirms); Cursor local-context.sh contains the session-start re-render logic; Cursor loop-detection uses /tmp/cursor-loop-detection-<key>. Behavioral deviation: the first run of CONTEXT_TASK_ID=qa-cursor-activation bash .cursor/hooks/working-memory-write.sh exited 0 but did NOT create working-memory.mdc — 'context.py context' failed with 'Working task not found' because the working task is only auto-provisioned after the flush threshold (flush-after=5 buffered turns). After 5 more buffered turns the capsule existed and a re-run of the stop hook rendered the rule correctly: frontmatter 'description: Working memory - Task Capsule as of end of previous turn', 'alwaysApply: true', '# Working Memory (auto-rendered)', fenced capsule, no diff/file contents or secrets inside, atomically replaced, ignored by git. | Q5: scratchpad/exec-hooks/laravel-cursor full edition copy incl. .cursor/rules/working-memory.mdc (temp copy) | R5: None in the real repo | S5: None | T5: 11 | U5: 10 | V5: 1 | W5: bash -n clean | X5: 0 | Y5: 1 | Z5: 0 | AA5: Expected behaviour item 4 ('After the stop hook runs, .cursor/rules/working-memory.mdc exists') does not hold on a fresh install: the rule is rendered only once the working task exists, which happens after 5 buffered turns (CONTEXT_FLUSH_AFTER default). First stop-hook run produced no rule file. | AB5: Accelerator-TestEvidence/TC-004.log | AC5: DEF-001 | AD5: Cursor in-IDE items (single session-context report, rule attachment to next prompt) require the live Cursor client and were not executed. All scriptable checks passed except the first-run render gap recorded as a defect.
A6: RUN-005 | B6: TC-005 | C6: 2026-08-03 | D6: Claude Fable 5 (scripted execution) | E6: 1.4.3 | F6: 3a02537 | G6: Laravel | H6: n/a (edition workspace) | I6: Codex | J6: n/a — scripted run (no AI client) | K6: n/a | L6: Governed | M6: Small | N6: Clean checkout at 3a02537; mutating steps ran in a temp copy | O6: Pass | P6: Script-part checks from Laravel/ root: .codex/config.toml contains '[features]' followed by 'hooks = true'; MCP example remains commented ('# [mcp_servers.github]'). .codex/hooks.json is valid JSON, wires SessionStart->local-context, UserPromptSubmit->working-memory-read (additionalContextLimit: 4000), Stop->working-memory-write, PreToolUse->bash-validator + file-naming-validator, PostToolUse->loop-detection, with no matcher on any group. Read payload piped to .codex/hooks/bash-validator.sh exited 0 silently (cheap self-filter, no extractor forked). Destructive payload {"command":"git push --force origin main"} exited 2 with stderr 'BLOCKED: Destructive command detected: matches pattern ...' and empty stdout. .codex/commands and .codex/agents both absent. .agents/skills contains verify, memory, project-brain, coder. .codex/hooks/local-context.sh printed the metadata-only banner and exited 0. | Q6: /tmp state only; evidence log | R6: None | S6: None | T6: 13 | U6: 13 | V6: 0 | W6: bash -n clean | X6: 0 | Y6: 0 | Z6: 0 | AB6: Accelerator-TestEvidence/TC-005.log | AD6: Trust-prompt gating (untrusted project must not load .codex config) and the live skills menu require the Codex CLI and were not executed; the scripted part fully matched, so Pass with that caveat.
A7: RUN-006 | B7: TC-007 | C7: 2026-08-03 | D7: Claude Fable 5 (scripted execution) | E7: 1.4.0 | F7: 3a02537 | G7: Infrastructure-Creator | H7: n/a (edition workspace) | I7: Claude Code | J7: n/a — scripted run (no AI client) | K7: n/a | L7: Not Applicable | M7: Small | N7: Clean checkout at 3a02537; mutating steps ran in a temp copy | O7: Partial | P7: The /infra-generate agent pipeline (forge fan-out, TASK profile consumption, report) cannot run scriptally, so the target was assembled by hand in a temp copy strictly following memory-seed/hook-forge/infra-generate SKILL.md instructions (verbatim asset copies, runtime.json substitutions generic/.claude, six hooks, quartet skills+agents+commands, stamped AGENTS.md, manifest via the exact SKILL.md recipe with version from the VERSION file). Every scriptable verification from the case then passed: validate_generated.py --editions claude exit 0 on first run; context.py status and validate both exit 0 from the target root; AGENTS.md first line matches 'Generated by Infrastructure-Creator v1.4.0 | TASK-1'; no .cursor/.codex/.agents roots exist; memory-quartet skill count is exactly 4; zero template placeholders in generated files. | Q7: exec-ic/fake-php-app/ full synthetic accelerator, build_green_target.sh (temp copy, scratchpad only) | R7: None | S7: None | T7: 7 | U7: 7 | V7: 0 | W7: bash -n clean on all 6 hook scripts | X7: 0 | Y7: 0 | Z7: 0 | AA7: LLM phases (profile re-validation, forge fan-out, infra-generate-report.md) require an interactive AI client run; only the structural/verification contract was executed | AB7: Accelerator-TestEvidence/TC-007.log | AD7: The bootstrap-verifier + manifest recipe + memory-seed asset contract is fully consistent: a target assembled exactly per the SKILL instructions verifies green on the first attempt. Repo tree confirmed clean after the run.
A8: RUN-007 | B8: TC-008 | C8: 2026-08-03 | D8: Claude Fable 5 (scripted execution) | E8: 1.4.0 | F8: 3a02537 | G8: Infrastructure-Creator | H8: n/a (edition workspace) | I8: Claude Code | J8: n/a — scripted run (no AI client) | K8: n/a | L8: Not Applicable | M8: Small | N8: Clean checkout at 3a02537; mutating steps ran in a temp copy | O8: Partial | P8: The interactive collision-guard dialogue cannot run scriptally; the merge mechanics were executed by hand per the SKILL: target built with a team-authored AGENTS.md and .claude/hooks/deploy-check.sh, preexisting-files.txt snapshotted before any writes, only missing files added, merge-mode manifest written via the exact SKILL.md recipe with the preexisting list. All four case verifications passed: sha256sum -c OK for both team files; manifest mode=merge, AGENTS.md and deploy-check.sh both absent from files; preexisting-files.txt lists AGENTS.md; validate_generated.py exit 0 (stamp check correctly skipped for the untracked team AGENTS.md, coverage correctly not enforced for merge). Additional probe found a defect: appending a normal 'TODO:' roadmap line to the team AGENTS.md makes the validator fail with 'leftover placeholder', because check_placeholders(AGENTS.md) runs unconditionally even when the file is a pre-existing untracked team file. | Q8: exec-ic/fake-php-app-merge/, exec-ic/task-3/preexisting-files.txt, tc008.sh (temp copies, scratchpad only) | R8: None | S8: None | T8: 7 | U8: 6 | V8: 1 | W8: Not Applicable | X8: 0 | Y8: 0 | Z8: 0 | AA8: Collision-guard stop/ask flow requires an interactive AI client; placeholder-scan defect found on team AGENTS.md | AB8: Accelerator-TestEvidence/TC-008.log | AC8: DEF-002 | AD8: Core safety property holds mechanically: pre-existing files are byte-identical after merge and never claimed by the manifest. The placeholder-scan gap is the only crack in the merge contract.
A9: RUN-008 | B9: TC-014 | C9: 2026-08-03 | D9: Claude Fable 5 (scripted execution) | E9: 1.4.0 | F9: 3a02537 | G9: Infrastructure-Creator | H9: n/a (edition workspace) | I9: Claude Code | J9: n/a — scripted run (no AI client) | K9: n/a | L9: Not Applicable | M9: Small | N9: Clean checkout at 3a02537; mutating steps ran in a temp copy | O9: Partial | P9: The infra-update agent cannot run scriptally; its step-5 classification table and Decision Memory rules were executed literally by a script (triage.py) against manifest + staged tree + target. Results: user-modified local-context.sh (hash != manifest) -> requires-decision, exactly 1 such row; untouched loop-detection.sh -> safe-update no-op; unmanifested .claude/skills-notes.md never iterated, read or reported (0 rows). 'Keep' decision applied per steps 7-8: AGENTS.md re-stamped TASK-2, manifest rewritten via the full recipe with a decisions entry {kept, 64-char rejected_sha256, TASK-2}; 'team tweak' still present (grep -c = 1); no staging dir inside the target. Regression run: staged sha == rejected_sha256 -> standing-decision-honored, file not overwritten; variant with changed generator output -> requires-decision again. Negative probes: validator rejects decision='replaced', a decisions entry for an untracked file, and a non-sha256 rejected_sha256. FAILED step: the case expects validate_generated.py exit 0 after the update, but it exits 1 with 'generated file not tracked: .claude/skills-notes.md' - full-mode coverage demands every file under .claude be manifest-tracked, contradicting infra-update's untouchable-file guardrail. | Q9: exec-ic/fake-php-app-update/, exec-ic/task-2-staging/, triage.py, tc014.sh (temp copies, scratchpad only) | R9: None | S9: None | T9: 11 | U9: 10 | V9: 1 | W9: Not Applicable | X9: 0 | Y9: 2 | Z9: 0 | AA9: validate_generated.py exit 1 instead of expected 0: full-mode coverage flags the team's untouchable .claude/skills-notes.md as 'generated file not tracked'; also interactive decision presentation and infra-update-report.md require an AI client | AB9: Accelerator-TestEvidence/TC-014.log | AC9: DEF-003 | AD9: Retries were harness-side only (a bash heredoc syntax slip, then an over-broad staging tree that wrongly included fixture files); the product checks behaved identically across runs. The classification and decision-memory mechanics themselves are sound and the validator enforces the decisions schema strictly.
A10: RUN-009 | B10: TC-015 | C10: 2026-08-03 | D10: Claude Fable 5 (scripted execution) | E10: 1.4.0 | F10: 3a02537 | G10: Infrastructure-Creator | H10: n/a (edition workspace) | I10: Claude Code | J10: n/a — scripted run (no AI client) | K10: n/a | L10: Not Applicable | M10: Small | N10: Clean checkout at 3a02537; mutating steps ran in a temp copy | O10: Partial | P10: Step 1 of infra-update was executed scriptally on a temp copy: manifest deleted, marker touched, sha256 baseline recorded; the scripted step attempted to load <target>/.infra-manifest.json, got FileNotFoundError and aborted with the legacy-generation explanation and both SKILL-mandated recovery options, fabricating nothing. Verifications: find -newer marker = 0 files, manifest still absent, all baseline sha256 OK - zero writes into the target before the abort. | Q10: exec-ic/fake-php-app-legacy/, exec-ic/pre-abort.sha256, exec-ic/update.marker (temp copies, scratchpad only) | R10: None | S10: None | T10: 4 | U10: 4 | V10: 0 | W10: Not Applicable | X10: 0 | Y10: 0 | Z10: 0 | AA10: The transcript-level expectations (agent phrasing of the legacy explanation and recovery options, refusal behavior under user pressure) require an interactive AI client run | AB10: Accelerator-TestEvidence/TC-015.log | AD10: The abort contract as written in infra-update SKILL.md step 1 is mechanically satisfiable with zero target writes; only agent-conversation fidelity remains unverified.
A11: RUN-010 | B11: TC-016 | C11: 2026-08-03 | D11: Claude Fable 5 (scripted execution) | E11: 1.4.0 | F11: 3a02537 | G11: Infrastructure-Creator | H11: n/a (edition workspace) | I11: Cursor | J11: n/a — scripted run (no AI client) | K11: n/a | L11: Not Applicable | M11: Small | N11: Clean checkout at 3a02537; mutating steps ran in a temp copy | O11: Partial | P11: hook-forge generation itself is LLM-only, so the hook contract was verified two ways. (1) A claude+cursor assembly built per the SKILL contract passed every case verification: 6 hooks in .claude/hooks; working-memory-read.sh deliberately absent from .cursor/hooks; all scripts bash -n clean and executable; zero terraform/kubectl rules in bash-validator (no IaC evidence in the fixture); .cursor/hooks.json version 1 with camelCase events and bare paths; zero interpreter-prefixed commands in settings.json; .cursor/rules/working-memory.mdc gitignored; working-memory-read.sh calls memory-bank/scripts/context.py at the fixed path; validate_generated.py --editions claude,cursor exit 0. Both negatives were caught by the validator: adding working-memory-read.sh to Cursor -> 'no prompt-time hook event' error; stripping the capsule render from the Cursor write hook -> 'does not render the alwaysApply working-memory rule' error. (2) The Infrastructure-Creator hook regression suite (tests/test_hooks.py) ran read-only: 21/21 tests OK, including mirror byte-identity and loop/naming/bash-validator behavior. | Q11: exec-ic/fake-php-app-cursor/, tc016.sh (temp copies, scratchpad only) | R11: None | S11: None | T11: 32 | U11: 32 | V11: 0 | W11: bash -n clean on all 11 hook scripts (6 claude + 5 cursor) | X11: 0 | Y11: 0 | Z11: 0 | AA11: Actual hook-forge generation (danger-rule derivation from profile sections 4/5/6, hook-forge-log.md with citations) requires an interactive AI client run | AB11: Accelerator-TestEvidence/TC-016.log | AD11: The Cursor read-path asymmetry is enforced in both directions by validate_generated.py, so a hook-forge run that violated it could not verify green. IC's own hook suite (21 tests) is fully green.
